<?xml version="1.0" ?>
<sdf version="1.5">
  <model name="m1013">
    <pose>0.0 0.0 0.0 0.0 0.0 0.0</pose>
    
    <link name="base"/>    

    <link name="base_0">
      <inertial>
        <inertia>
          <ixx>0.001</ixx>
          <ixy>0.000</ixy>
          <ixz>0.000</ixz>
          <iyy>0.001</iyy>
          <iyz>0.000</iyz>
          <izz>0.001</izz>
        </inertia>
        <mass>3.7</mass>
      </inertial>
      
      <visual name="base_0_visual">
          <geometry>
            <mesh>
              <uri>model://m1013/meshes/MF1013_0_0.dae</uri>
              <scale>0.001 0.001 0.001</scale>
            </mesh>
          </geometry>
      </visual>
    </link>

    <link name="link1">
      <inertial>
        <inertia>
          <ixx>0.001</ixx>
          <ixy>0.000</ixy>
          <ixz>0.000</ixz>
          <iyy>0.001</iyy>
          <iyz>0.000</iyz>
          <izz>0.001</izz>
        </inertia>
        <pose>7e-05 0.044281 0.143327 0 0 0</pose>
        <mass>3.7</mass>
      </inertial>

      <visual name="link1_visual">
        <pose>0 0 0.1525 0 0 0</pose>
        <geometry>
          <mesh>
            <uri>model://m1013/meshes/MF1013_1_0.dae</uri>
            <scale>0.001 0.001 0.001</scale>
          </mesh>
        </geometry>
      </visual>
    </link>

    <link name="link2">
      <inertial>
        <inertia>
          <ixx>0.001</ixx>
          <ixy>0.000</ixy>
          <ixz>0.000</ixz>
          <iyy>0.001</iyy>
          <iyz>0.000</iyz>
          <izz>0.001</izz>
        </inertia>
        <mass>3.7</mass>
      </inertial>

      <visual name="link2_0_visual">
      <pose>0 0.0345 0.1525 0 -1.571 -1.571</pose>
        <geometry>
          <mesh>
            <uri>model://m1013/meshes/MF1013_2_0.dae</uri>
            <scale>0.001 0.001 0.001</scale>
          </mesh>
        </geometry>
      </visual>
      <visual name="link2_1_visual">
      <pose>0 0.0345 0.1525 0 -1.571 -1.571</pose>
        <geometry>
          <mesh>
            <uri>model://m1013/meshes/MF1013_2_1.dae</uri>
            <scale>0.001 0.001 0.001</scale>
          </mesh>
        </geometry>
      </visual>
      <visual name="link2_2_visual">
      <pose>0 0.0345 0.1525 0 -1.571 -1.571</pose>
        <geometry>
          <mesh>
            <uri>model://m1013/meshes/MF1013_2_2.dae</uri>
            <scale>0.001 0.001 0.001</scale>
          </mesh>
        </geometry>
      </visual>
    </link>

    <joint name="fixed_base" type="fixed">
      <parent>world</parent>
      <child>base_0</child>
    </joint>

    <joint name="joint1" type="revolute">
      <parent>base_0</parent>
      <child>link1</child>
      <pose>0 0 0.1525 0 0 0</pose>
      <axis>
        <xyz>0 0 1</xyz>
      </axis>
    </joint>

    <joint name="joint2" type="revolute">
      <parent>link1</parent>
      <child>link2</child>
      <pose>0 0.0345 0 0 -1.571 -1.571</pose>
      <axis>
        <xyz>0 0 1</xyz>
      </axis>
    </joint>


  </model>
</sdf>
